Workbook

Sheet Balance
B1: AMAT Historical Balance Sheet | C1: INPUT | J1: Invested Capital
B2: $ millions | C2: OCT '18 | D2: OCT '19 | E2: OCT '20 | F2: OCT '21 | G2: OCT '22 | H2: OCT '23 | J2: $ millions | K2: =C2 -> OCT '18 | L2: =D2 -> OCT '19 | M2: =E2 -> OCT '20 | N2: =F2 -> OCT '21 | O2: =G2 -> OCT '22 | P2: =H2 -> OCT '23
C3: Restate | K3: =C3 -> Restate | L3: =D3 -> 0 | M3: =E3 -> 0 | N3: =F3 -> 0 | O3: =G3 -> 0 | P3: =H3 -> 0
B4: Assets | J4: Working cash | K4: =+K39*0.02 -> 334.1 | L4: =+L39*0.02 -> 292.16 | M4: =+M39*0.02 -> 344 | N4: =+N39*0.02 -> 461.18 | O4: =+O39*0.02 -> 513.7 | P4: =+P39*0.02 -> 529.08
B5: Cash & Short-Term Investments | C5: 4030 | D5: 3618 | E5: 5738 | F5: 5459 | G5: 2581 | H5: 6869 | J5: Short-Term Receivables | K5: =C8 -> 2422 | L5: =D8 -> 2641 | M5: =E8 -> 3111 | N5: =F8 -> 5154 | O5: =G8 -> 6241 | P5: =H8 -> 5439
B6: Cash Only | C6: 3440 | D6: 3129 | E6: 5351 | F6: 4995 | G6: 1995 | H6: 6132 | J6: Inventories | K6: =C12 -> 3721 | L6: =D12 -> 3474 | M6: =E12 -> 3904 | N6: =F12 -> 4309 | O6: =G12 -> 5932 | P6: =H12 -> 5725
B7: Total Short Term Investments | C7: 590 | D7: 489 | E7: 387 | F7: 464 | G7: 586 | H7: 737 | J7: Other Current Assets | K7: =C17 -> 431 | L7: =D17 -> 473 | M7: =E17 -> 616 | N7: =F17 -> 1185 | O7: =G17 -> 1171 | P7: =H17 -> 1114
B8: Short-Term Receivables | C8: 2422 | D8: 2641 | E8: 3111 | F8: 5154 | G8: 6241 | H8: 5439 | J8: Operating current assets | K8: =SUM(K4:K7) -> 6908.1 | L8: =SUM(L4:L7) -> 6880.16 | M8: =SUM(M4:M7) -> 7975 | N8: =SUM(N4:N7) -> 11109.18 | O8: =SUM(O4:O7) -> 13857.7 | P8: =SUM(P4:P7) -> 12807.08
B9: Accounts Receivables, Net | C9: 2422 | D9: 2641 | E9: 3111 | F9: 5154 | G9: 6241 | H9: 5439
B10: Accounts Receivables, Gross | C10: 2455 | D10: 2671 | E10: 3141 | F10: 5183 | G10: 6270 | H10: 5468 | J10: Accounts Payable | K10: =C44 -> 996 | L10: =D44 -> 958 | M10: =E44 -> 1124 | N10: =F44 -> 1472 | O10: =G44 -> 1755 | P10: =H44 -> 1478
B11: Bad Debt/Doubtful Accounts | C11: -33 | D11: -30 | E11: -30 | F11: -29 | G11: -29 | H11: -29 | J11: Income Tax Payable | K11: =C45 -> 136 | L11: =D45 -> 160 | M11: =E45 -> 222 | N11: =F45 -> 734 | O11: =G45 -> 319 | P11: =H45 -> 282
B12: Inventories | C12: 3721 | D12: 3474 | E12: 3904 | F12: 4309 | G12: 5932 | H12: 5725 | J12: Other Current Liabilities | K12: =C46 -> 2790 | L12: =D46 -> 2729 | M12: =E46 -> 3049 | N12: =F46 -> 4065 | O12: =G46 -> 5220 | P12: =H46 -> 5326
B13: Finished Goods | C13: 1207 | D13: 852 | E13: 1140 | F13: 1049 | G13: 1687 | H13: 1486 | J13: Operating current liabilities | K13: =SUM(K10:K12) -> 3922 | L13: =SUM(L10:L12) -> 3847 | M13: =SUM(M10:M12) -> 4395 | N13: =SUM(N10:N12) -> 6271 | O13: =SUM(O10:O12) -> 7294 | P13: =SUM(P10:P12) -> 7086
B14: Work in Progress | C14: 505 | D14: 575 | E14: 624 | F14: 873 | G14: 1029 | H14: 997
B15: Raw Materials | C15: 1020 | D15: 802 | E15: 870 | F15: 1136 | G15: 1807 | H15: 1653 | J15: Operating working capital | K15: =+K8-K13 -> 2986.1 | L15: =+L8-L13 -> 3033.16 | M15: =+M8-M13 -> 3580 | N15: =+N8-N13 -> 4838.18 | O15: =+O8-O13 -> 6563.7 | P15: =+P8-P13 -> 5721.08
B16: Progress Payments & Other | C16: 989 | D16: 1245 | E16: 1270 | F16: 1251 | G16: 1409 | H16: 1589 | J16: Net Property, Plant & Equipment | K16: =C22 -> 1407 | L16: =D22 -> 1529 | M16: =E22 -> 1856 | N16: =F22 -> 2228 | O16: =G22 -> 2696 | P16: =H22 -> 3201
B17: Other Current Assets | C17: 431 | D17: 473 | E17: 616 | F17: 1185 | G17: 1171 | H17: 1114 | J17: Capitalized Operating Leases(Hidden Asset) | K17: =+K41 -> 0 | L17: =+L41 -> 0 | M17: =+M41 -> 0 | N17: =+N41 -> 0 | O17: =+O41 -> 0 | P17: =+P41 -> 0
B18: Prepaid Expenses | J18: Intangible Assets | K18: =C34 -> 3581 | L18: =D34 -> 3555 | M18: =E34 -> 3619 | N18: =F34 -> 3583 | O18: =G34 -> 4039 | P18: =H34 -> 4026
B19: Miscellaneous Current Assets | C19: 431 | D19: 473 | E19: 616 | F19: 1185 | G19: 1171 | H19: 1114 | J19: Net Other Operating Assets | K19: =C38-C58 -> -1120 | L19: =D38-D58 -> -1162 | M19: =E38-E58 -> -1172 | N19: =F38-F58 -> -1132 | O19: =G38-G58 -> -611 | P19: =H38-H58 -> -824
B20: Total Current Assets | C20: 10604 | D20: 10206 | E20: 13369 | F20: 16107 | G20: 15925 | H20: 19147 | J20: Invested capital (Uses) | K20: =SUM(K15:K19) -> 6854.1 | L20: =SUM(L15:L19) -> 6955.16 | M20: =SUM(M15:M19) -> 7883 | N20: =SUM(N15:N19) -> 9517.18 | O20: =SUM(O15:O19) -> 12687.7 | P20: =SUM(P15:P19) -> 12124.08
J21: Net investment | L21: =L20-K20 -> 101.06 | M21: =M20-L20 -> 927.84 | N21: =N20-M20 -> 1634.18 | O21: =O20-N20 -> 3170.52 | P21: =P20-O20 -> -563.62
B22: Net Property, Plant & Equipment | C22: 1407 | D22: 1529 | E22: 1856 | F22: 2228 | G22: 2696 | H22: 3201
B23: Property, Plant & Equipment - Gross | C23: 3812 | D23: 4071 | E23: 4632 | F23: 5274 | G23: 6018 | H23: 6852 | J23: Excess cash | K23: =C5-K4 -> 3695.9 | L23: =D5-L4 -> 3325.84 | M23: =E5-M4 -> 5394 | N23: =F5-N4 -> 4997.82 | O23: =G5-O4 -> 2067.3 | P23: =H5-P4 -> 6339.92
B24: Buildings | C24: 1448 | D24: 1590 | E24: 1655 | F24: 1780 | G24: 2027 | H24: 2194 | J24: Total Investments and Advances | K24: =C32 -> 1568 | L24: =D32 -> 1703 | M24: =E32 -> 1538 | N24: =F32 -> 2055 | O24: =G32 -> 1980 | P24: =H32 -> 2281
B25: Land & Improvements | C25: 245 | D25: 254 | E25: 256 | F25: 334 | G25: 387 | H25: 393 | J25: NOA | K25: =SUM(K23:K24) -> 5263.9 | L25: =SUM(L23:L24) -> 5028.84 | M25: =SUM(M23:M24) -> 6932 | N25: =SUM(N23:N24) -> 7052.82 | O25: =SUM(O23:O24) -> 4047.3 | P25: =SUM(P23:P24) -> 8620.92
B26: Machinery & Equipment | C26: 1282 | D26: 1505 | E26: 1586 | F26: 1820 | G26: 2083 | H26: 2353 | J26: Total funds invested (Uses) | K26: =K20+K25 -> 12118 | L26: =L20+L25 -> 11984 | M26: =M20+M25 -> 14815 | N26: =N20+N25 -> 16570 | O26: =O20+O25 -> 16735 | P26: =P20+P25 -> 20745 | Q26: IC + NOA
B27: Construction in Progress | C27: 203 | D27: 120 | E27: 237 | F27: 326 | G27: 389 | H27: 672
B28: Leases | C28: 0 | D28: 0 | E28: 0 | F28: 0 | G28: 0 | H28: 108 | J28: ST Debt & Curr. Portion LT Debt | K28: =C43 -> 0 | L28: =D43 -> 600 | M28: =E43 -> 64 | N28: =F43 -> 73 | O28: =G43 -> 85 | P28: =H43 -> 286
B29: Other Property, Plant & Equipment | C29: 634 | D29: 602 | E29: 646 | F29: 720 | G29: 743 | H29: 762 | J29: Long-Term Debt | K29: =C52 -> 5309 | L29: =D52 -> 4713 | M29: =E52 -> 5643 | N29: =F52 -> 5680 | O29: =G52 -> 5744 | P29: =H52 -> 5713
B30: Operating Lease Right-of-Use Assets | E30: 252 | F30: 294 | G30: 389 | H30: 370 | J30: Provision for Risks & Charges | K30: =C55 -> 177 | L30: =D55 -> 212 | M30: =E55 -> 241 | N30: =F55 -> 193 | O30: =G55 -> 107 | P30: =H55 -> 126
B31: Accumulated Depreciation | C31: 2405 | D31: 2542 | E31: 2776 | F31: 3046 | G31: 3322 | H31: 3651 | J31: Capitalized operating leases(Debt Equivalent) | K31: =K41 -> 0 | L31: =L41 -> 0 | M31: =M41 -> 0 | N31: =N41 -> 0 | O31: =O41 -> 0 | P31: =P41 -> 0
B32: Total Long-Term Investments | C32: 1568 | D32: 1703 | E32: 1538 | F32: 2055 | G32: 1980 | H32: 2281 | J32: Debt and debt equivalents | K32: =SUM(K28:K31) -> 5486 | L32: =SUM(L28:L31) -> 5525 | M32: =SUM(M28:M31) -> 5948 | N32: =SUM(N28:N31) -> 5946 | O32: =SUM(O28:O31) -> 5936 | P32: =SUM(P28:P31) -> 6125
B33: Other Long-Term Investments | C33: 1568 | D33: 1703 | E33: 1538 | F33: 2055 | G33: 1980 | H33: 2281 | J33: Total Equity | K33: =C70 -> 6845 | L33: =D70 -> 8214 | M33: =E70 -> 10578 | N33: =F70 -> 12247 | O33: =G70 -> 12194 | P33: =H70 -> 16349
B34: Intangible Assets | C34: 3581 | D34: 3555 | E34: 3619 | F34: 3583 | G34: 4039 | H34: 4026 | J34: Net Deferred Tax Liabilities | K34: =C56-C37 -> -213 | L34: =D56-D37 -> -1755 | M34: =E56-E37 -> -1711 | N34: =F56-F37 -> -1623 | O34: =G56-G37 -> -1395 | P34: =H56-H37 -> -1729
B35: Goodwill | C35: 3368 | D35: 3399 | E35: 3466 | F35: 3479 | G35: 3700 | H35: 3732
B36: Other Intangible Assets | C36: 213 | D36: 156 | E36: 153 | F36: 104 | G36: 339 | H36: 294 | J36: Equity and equity equivalents | K36: =SUM(K33:K35) -> 6632 | L36: =SUM(L33:L35) -> 6459 | M36: =SUM(M33:M35) -> 8867 | N36: =SUM(N33:N35) -> 10624 | O36: =SUM(O33:O35) -> 10799 | P36: =SUM(P33:P35) -> 14620
B37: Deferred Tax Assets | C37: 225 | D37: 1766 | E37: 1711 | F37: 1623 | G37: 1395 | H37: 1729 | J37: Total funds invested (Sources) | K37: =+K32+K36 -> 12118 | L37: =+L32+L36 -> 11984 | M37: =+M32+M36 -> 14815 | N37: =+N32+N36 -> 16570 | O37: =+O32+O36 -> 16735 | P37: =+P32+P36 -> 20745 | Q37: debt + equity equivalents
B38: Other Assets | C38: 260 | D38: 276 | E38: 260 | F38: 229 | G38: 691 | H38: 345
B39: Tangible Other Assets | C39: 260 | D39: 276 | E39: 260 | F39: 229 | G39: 691 | H39: 345 | J39: Net sales | K39: =Income!C$4 -> 16705 | L39: =Income!D$4 -> 14608 | M39: =Income!E$4 -> 17200 | N39: =Income!F$4 -> 23059 | O39: =Income!G$4 -> 25685 | P39: =Income!H$4 -> 26454
B40: Total Assets | C40: 17645 | D40: 19035 | E40: 22353 | F40: 25825 | G40: 26726 | H40: 30729 | J40: PV of operating lease payments @
...

Sheet Income
B1: AMAT Historical Income Statement | C1: Restate
B2: $ millions | C2: OCT '18 | D2: OCT '19 | E2: OCT '20 | F2: OCT '21 | G2: OCT '22 | H2: OCT '23
B4: Sales | C4: 16705 | D4: 14608 | E4: 17200 | F4: 23059 | G4: 25685 | H4: 26454
B5: Cost of Goods Sold (COGS) incl. D&A | C5: 9230 | D5: 8258 | E5: 9532 | F5: 12169 | G5: 13793 | H5: 14133 | L5: =C2 -> OCT '18 | M5: =D2 -> OCT '19 | N5: =E2 -> OCT '20 | O5: =F2 -> OCT '21 | P5: =G2 -> OCT '22 | Q5: =H2 -> OCT '23
B6: COGS excluding D&A | C6: 8773 | D6: 7895 | E6: 9156 | F6: 11775 | G6: 13349 | H6: 13618 | K6: NOPLAT | L6: =C3 -> 0 | M6: =D3 -> 0 | N6: =E3 -> 0 | O6: =F3 -> 0 | P6: =G3 -> 0 | Q6: =H3 -> 0
B7: Depreciation & Amortization Expense | C7: 457 | D7: 363 | E7: 376 | F7: 394 | G7: 444 | H7: 515 | K7: Sales | L7: =C4 -> 16705 | M7: =D4 -> 14608 | N7: =E4 -> 17200 | O7: =F4 -> 23059 | P7: =G4 -> 25685 | Q7: =H4 -> 26454
B8: Depreciation | C8: 258 | D8: 306 | E8: 320 | F8: 345 | G8: 404 | H8: 471 | K8: COGS excluding D&A | L8: =-C6 -> -8773 | M8: =-D6 -> -7895 | N8: =-E6 -> -9156 | O8: =-F6 -> -11775 | P8: =-G6 -> -13349 | Q8: =-H6 -> -13618
B9: Amortization of Intangibles | C9: 199 | D9: 57 | E9: 56 | F9: 49 | G9: 40 | H9: 44 | K9: Other SG&A | L9: =-C13 -> -971 | M9: =-D13 -> -947 | N9: =-E13 -> -1076 | O9: =-F13 -> -1211 | P9: =-G13 -> -1419 | Q9: =-H13 -> -1622
B10: Gross Income | C10: 7475 | D10: 6350 | E10: 7668 | F10: 10890 | G10: 11892 | H10: 12321 | K10: Research & Development | L10: =-C12 -> -2021 | M10: =-D12 -> -2053 | N10: =-E12 -> -2237 | O10: =-F12 -> -2481 | P10: =-G12 -> -2777 | Q10: =-H12 -> -3116
B11: SG&A Expense | C11: 2992 | D11: 3000 | E11: 3313 | F11: 3692 | G11: 4196 | H11: 4738 | K11: Depreciation & Amortization Expense | L11: =-C7 -> -457 | M11: =-D7 -> -363 | N11: =-E7 -> -376 | O11: =-F7 -> -394 | P11: =-G7 -> -444 | Q11: =-H7 -> -515
B12: Research & Development | C12: 2021 | D12: 2053 | E12: 2237 | F12: 2481 | G12: 2777 | H12: 3116 | K12: Earnings before interest & taxes (EBIT) | L12: =SUM(L7:L11) -> 4483 | M12: =SUM(M7:M11) -> 3350 | N12: =SUM(N7:N11) -> 4355 | O12: =SUM(O7:O11) -> 7198 | P12: =SUM(P7:P11) -> 7696 | Q12: =SUM(Q7:Q11) -> 7583
B13: Other SG&A | C13: 971 | D13: 947 | E13: 1076 | F13: 1211 | G13: 1419 | H13: 1622 | K13: Operating lease interest | L13: =Balance!K17*Balance!K40 -> 0 | M13: =Balance!L17*Balance!L40 -> 0 | N13: =Balance!M17*Balance!M40 -> 0 | O13: =Balance!N17*Balance!N40 -> 0 | P13: =Balance!O17*Balance!O40 -> 0 | Q13: =Balance!P17*Balance!P40 -> 0
B14: EBIT (Operating Income) | C14: 4483 | D14: 3350 | E14: 4355 | F14: 7198 | G14: 7696 | H14: 7583 | K14: Adjusted EBIT | L14: =SUM(L12:L13) -> 4483 | M14: =SUM(M12:M13) -> 3350 | N14: =SUM(N12:N13) -> 4355 | O14: =SUM(O12:O13) -> 7198 | P14: =SUM(P12:P13) -> 7696 | Q14: =SUM(Q12:Q13) -> 7583
B15: Nonoperating Income - Net | C15: 142 | D15: 123 | E15: 76 | F15: 32 | G15: 53 | H15: 364 | K15: Operating cash taxes | L15: =-L16*L14 -> -1384.8758 | M15: =-M16*M14 -> -576.95014 | N15: =-N16*N14 -> -571.81589 | O15: =-O16*O14 -> -938.68468 | P15: =-P16*P14 -> -1087.7094 | Q15: =-Q16*Q14 -> -845.17626
B16: Other Income (Expense) | C16: 142 | D16: 123 | E16: 76 | F16: 32 | G16: 53 | H16: 364 | K16: Tax rate | L16: =C30/C29 -> 0.3089172 | M16: =D30/D29 -> 0.17222392 | N16: =E30/E29 -> 0.13130101 | O16: =F30/F29 -> 0.1304091 | P16: =G30/G29 -> 0.14133439 | Q16: =H30/H29 -> 0.11145671
B17: Interest Expense | C17: 231 | D17: 234 | E17: 233 | F17: 223 | G17: 215 | H17: 225 | K17: NOPLAT | L17: =SUM(L14:L15) -> 3098.1242 | M17: =SUM(M14:M15) -> 2773.0499 | N17: =SUM(N14:N15) -> 3783.1841 | O17: =SUM(O14:O15) -> 6259.3153 | P17: =SUM(P14:P15) -> 6608.2906 | Q17: =SUM(Q14:Q15) -> 6737.8237
B18: Gross Interest Expense | C18: 231 | D18: 234 | E18: 233 | F18: 223 | G18: 215 | H18: 225 | K18: ROIC | L18: =+L17/Balance!$K$20 -> 0.45201036 | M18: =+M17/Balance!$L$20 -> 0.39870396 | N18: =+N17/Balance!$M$20 -> 0.4799168 | O18: =+O17/Balance!$N$20 -> 0.65768592 | P18: =+P17/Balance!O20 -> 0.52084228 | Q18: =+Q17/Balance!P20 -> 0.55573897
B19: Unusual Expense - Net | C19: -2 | D19: -30 | E19: 32 | F19: 236 | G19: -65 | H19: 6
B20: Impairments | C20: 5 | D20: 1 | E20: 8 | F20: 7 | G20: 7 | H20: 125 | K20: Net investment | M20: =Balance!L21 -> 101.06 | N20: =Balance!M21 -> 927.84 | O20: =Balance!N21 -> 1634.18 | P20: =Balance!O21 -> 3170.52 | Q20: =Balance!P21 -> -563.62
B21: Financial Fixed Assets | C21: 5 | D21: 1 | E21: 8 | F21: 7 | G21: 7 | H21: 125 | K21: Free cash flow | M21: =M17-M20 -> 2671.9899 | N21: =N17-N20 -> 2855.3441 | O21: =O17-O20 -> 4625.1353 | P21: =P17-P20 -> 3437.7706 | Q21: =Q17-Q20 -> 7301.4437
B22: Restructuring Expense | C22: 0 | D22: 0 | E22: 0 | F22: 311 | G22: -4 | H22: 0
B23: Unrealized Valuation Gain/Loss | C23: 7 | D23: 31 | E23: 9 | F23: 82 | G23: 68 | H23: 119
B24: Investments | D24: 30 | E24: 8 | F24: 56 | G24: 4 | H24: 134
B25: Hedges/Derivatives | C25: 7 | D25: 1 | E25: 1 | F25: 26 | G25: 64 | H25: -15
B26: Excpl Chrgs - Others | E26: 33
B27: Restructuring of Debt | E27: 33
B28: Other Unusual Expense
B29: Pretax Income | C29: 4396 | D29: 3269 | E29: 4166 | F29: 6771 | G29: 7599 | H29: 7716
B30: Income Taxes | C30: 1358 | D30: 563 | E30: 547 | F30: 883 | G30: 1074 | H30: 860
B31: Income Taxes - Current Domestic | C31: 1043 | D31: 252 | E31: 216 | F31: 479 | G31: 604 | H31: 762
B32: Income Taxes - Current Foreign | C32: 117 | D32: 260 | E32: 263 | F32: 344 | G32: 275 | H32: 456
B33: Income Taxes - Deferred Domestic | C33: 141 | D33: 5 | E33: -8 | F33: -7 | G33: -70 | H33: -297
B34: Income Taxes - Deferred Foreign | C34: 57 | D34: 46 | E34: 76 | F34: 67 | G34: 265 | H34: -61
B35: Consolidated Net Income | C35: 3038 | D35: 2706 | E35: 3619 | F35: 5888 | G35: 6525 | H35: 6856
B36: Net Income | C36: 3038 | D36: 2706 | E36: 3619 | F36: 5888 | G36: 6525 | H36: 6856
B37: Net Income available to Common | C37: 3038 | D37: 2706 | E37: 3619 | F37: 5888 | G37: 6525 | H37: 6856
B38: Per Share
B39: EPS (recurring) | C39: 2.959649 | D39: 2.84127 | E39: 3.945179 | F39: 6.586725 | G39: 7.388255 | H39: 8.11858
B40: EPS (basic) | C40: 2.999 | D40: 2.8879 | E40: 3.9509 | F40: 6.4703 | G40: 7.4914 | H40: 8.1619
B41: Basic Shares Outstanding | C41: 1013 | D41: 937 | E41: 916 | F41: 910 | G41: 871 | H41: 840
...

Sheet Forecast
B1: AAPL Financial Analysis | C1: =Income!C2 -> OCT '18 | D1: =Income!D2 -> OCT '19 | E1: =Income!E2 -> OCT '20 | F1: =Income!F2 -> OCT '21 | G1: =Income!G2 -> OCT '22 | H1: =Income!H2 -> OCT '23 | I1: OCT'24 | J1: OCT'25 | K1: OCT'26 | L1: OCT'27 | M1: OCT'28 | N1: OCT'29
C2: =Income!C3 -> 0 | D2: =Income!D3 -> 0 | E2: =Income!E3 -> 0 | F2: =Income!F3 -> 0 | G2: =Income!G3 -> 0 | H2: =Income!H3 -> 0
B4: Operating working capital | C4: =Balance!K15 -> 2986.1 | D4: =Balance!L15 -> 3033.16 | E4: =Balance!M15 -> 3580 | F4: =Balance!N15 -> 4838.18 | G4: =Balance!O15 -> 6563.7 | H4: =Balance!P15 -> 5721.08 | I4: =I22*I5 -> 5860.6744 | J4: =J22*J5 -> 6553.9921 | K4: =K22*K5 -> 7131.3988 | L4: =L22*L5 -> 7487.9688 | M4: =M22*M5 -> 7899.8071 | N4: =N22*N5 -> 8373.7955
B5: Operating working capital/net sales | C5: =+C4/C22 -> 0.17875486 | D5: =+D4/D22 -> 0.20763691 | E5: =+E4/E22 -> 0.20813953 | F5: =+F4/F22 -> 0.20981742 | G5: =+G4/G22 -> 0.25554604 | H5: =+H4/H22 -> 0.21626522 | I5: =H5 -> 0.21626522 | J5: =I5 -> 0.21626522 | K5: =J5 -> 0.21626522 | L5: =K5 -> 0.21626522 | M5: =L5 -> 0.21626522 | N5: =M5 -> 0.21626522
B6: Net property, plant & equipment | C6: =Balance!K16 -> 1407 | D6: =Balance!L16 -> 1529 | E6: =Balance!M16 -> 1856 | F6: =Balance!N16 -> 2228 | G6: =Balance!O16 -> 2696 | H6: =Balance!P16 -> 3201 | I6: =I22*I7 -> 3279.1044 | J6: =J22*J7 -> 3667.0225 | K6: =K22*K7 -> 3990.0871 | L6: =L22*L7 -> 4189.5915 | M6: =M22*M7 -> 4420.019 | N6: =N22*N7 -> 4685.2202
B7: Net PP&E/net sales | C7: =+C6/C22 -> 0.08422628 | D7: =+D6/D22 -> 0.10466867 | E7: =+E6/E22 -> 0.10790698 | F7: =+F6/F22 -> 0.09662171 | G7: =+G6/G22 -> 0.10496399 | H7: =+H6/H22 -> 0.12100249 | I7: =H7 -> 0.12100249 | J7: =I7 -> 0.12100249 | K7: =J7 -> 0.12100249 | L7: =K7 -> 0.12100249 | M7: =L7 -> 0.12100249 | N7: =M7 -> 0.12100249
B8: Capitalized operating leases | C8: =Balance!K17 -> 0 | D8: =Balance!L17 -> 0 | E8: =Balance!M17 -> 0 | F8: =Balance!N17 -> 0 | G8: =Balance!O17 -> 0 | H8: =Balance!P17 -> 0 | I8: =I22*I9 -> 0 | J8: =J22*J9 -> 0 | K8: =K22*K9 -> 0 | L8: =L22*L9 -> 0 | M8: =M22*M9 -> 0 | N8: =N22*N9 -> 0
B9: Capitalized operating leases/net sales | C9: =+C8/C22 -> 0 | D9: =+D8/D22 -> 0 | E9: =+E8/E22 -> 0 | F9: =+F8/F22 -> 0 | G9: =+G8/G22 -> 0 | H9: =+H8/H22 -> 0 | I9: =H9 -> 0 | J9: =I9 -> 0 | K9: =J9 -> 0 | L9: =K9 -> 0 | M9: =L9 -> 0 | N9: =M9 -> 0
B10: Intangibles | C10: =Balance!K18 -> 3581 | D10: =Balance!L18 -> 3555 | E10: =Balance!M18 -> 3619 | F10: =Balance!N18 -> 3583 | G10: =Balance!O18 -> 4039 | H10: =Balance!P18 -> 4026 | I10: =I22*I11 -> 4124.2344 | J10: =J22*J11 -> 4612.1313 | K10: =K22*K11 -> 5018.4601 | L10: =L22*L11 -> 5269.3831 | M10: =M22*M11 -> 5559.1992 | N10: =N22*N11 -> 5892.7511
B11: Net other assets/net sales | C11: =C10/C22 -> 0.21436696 | D11: =D10/D22 -> 0.2433598 | E11: =E10/E22 -> 0.21040698 | F11: =F10/F22 -> 0.15538401 | G11: =G10/G22 -> 0.15725131 | H11: =H10/H22 -> 0.1521887 | I11: =H11 -> 0.1521887 | J11: =I11 -> 0.1521887 | K11: =J11 -> 0.1521887 | L11: =K11 -> 0.1521887 | M11: =L11 -> 0.1521887 | N11: =M11 -> 0.1521887
B12: Net other assets | C12: =Balance!K19 -> -1120 | D12: =Balance!L19 -> -1162 | E12: =Balance!M19 -> -1172 | F12: =Balance!N19 -> -1132 | G12: =Balance!O19 -> -611 | H12: =Balance!P19 -> -824 | I12: =I22*I13 -> -844.1056 | J12: =J22*J13 -> -943.96329 | K12: =K22*K13 -> -1027.1265 | L12: =L22*L13 -> -1078.4828 | M12: =M22*M13 -> -1137.7993 | N12: =N22*N13 -> -1206.0673
B13: Net other assets/net sales | C13: =C12/C22 -> -0.067045795 | D13: =D12/D22 -> -0.079545455 | E13: =E12/E22 -> -0.068139535 | F13: =F12/F22 -> -0.049091461 | G13: =G12/G22 -> -0.023788203 | H13: =H12/H22 -> -0.031148409 | I13: =H13 -> -0.031148409 | J13: =I13 -> -0.031148409 | K13: =J13 -> -0.031148409 | L13: =K13 -> -0.031148409 | M13: =L13 -> -0.031148409 | N13: =M13 -> -0.031148409
B14: Invested capital (Uses) | C14: =C4+C6+C8+C10+C12 -> 6854.1 | D14: =D4+D6+D8+D10+D12 -> 6955.16 | E14: =E4+E6+E8+E10+E12 -> 7883 | F14: =F4+F6+F8+F10+F12 -> 9517.18 | G14: =G4+G6+G8+G10+G12 -> 12687.7 | H14: =H4+H6+H8+H10+H12 -> 12124.08 | I14: =I4+I6+I8+I10+I12 -> 12419.908 | J14: =J4+J6+J8+J10+J12 -> 13889.183 | ... N14: =N4+N6+N8+N10+N12 -> 17745.699
B16: Net investment | D16: =+D14-C14 -> 101.06 | E16: =+E14-D14 -> 927.84 | F16: =+F14-E14 -> 1634.18 | G16: =G14-F14 -> 3170.52 | H16: =H14-G14 -> -563.62 | I16: =I14-H14 -> 295.82755 | J16: =J14-I14 -> 1469.2751 | K16: =K14-J14 -> 1223.637 | L16: =L14-K14 -> 755.64098 | M16: =M14-L14 -> 872.76533 | N16: =N14-M14 -> 1004.4736
B17: Investment rate (net investment/NOPLAT) | D17: =+D16/D41 -> 0.036443629 | E17: =+E16/E41 -> 0.24525373 | F17: =+F16/F41 -> 0.26107967 | G17: =+G16/G41 -> 0.47977915 | H17: =+H16/H41 -> -0.083650155
B18: Adjusted Debt (DDE - NOA) | C18: =Balance!K32-Balance!K25 -> 222.1 | D18: =Balance!L32-Balance!L25 -> 496.16 | E18: =Balance!M32-Balance!M25 -> -984 | F18: =Balance!N32-Balance!N25 -> -1106.82 | G18: =Balance!O32-Balance!O25 -> 1888.7 | H18: =Balance!P32-Balance!P25 -> -2495.92
B19: Equity (EEE) | C19: =Balance!K36 -> 6632 | D19: =Balance!L36 -> 6459 | E19: =Balance!M36 -> 8867 | F19: =Balance!N36 -> 10624 | G19: =Balance!O36 -> 10799 | H19: =Balance!P36 -> 14620
B20: Invested capital (Sources) | C20: =SUM(C18:C19) -> 6854.1 | D20: =SUM(D18:D19) -> 6955.16 | E20: =SUM(E18:E19) -> 7883 | F20: =SUM(F18:F19) -> 9517.18 | G20: =SUM(G18:G19) -> 12687.7 | H20: =SUM(H18:H19) -> 12124.08
B22: Net sales | C22: =Income!L7 -> 16705 | D22: =Income!M7 -> 14608 | E22: =Income!N7 -> 17200 | F22: =Income!O7 -> 23059 | G22: =Income!P7 -> 25685 | H22: =Income!Q7 -> 26454 | I22: =H22*(1+I23) -> 27099.478 | J22: =I22*(1+J23) -> 30305.346 | K22: =J22*(1+K23) -> 32975.247 | L22: =K22*(1+L23) -> 34624.009 | M22: =L22*(1+M23) -> 36528.33 | N22: =M22*(1+N23) -> 38720.029
B23: Net sales growth | D23: =(D22/C22)-1 -> -0.12553128 | E23: =(E22/D22)-1 -> 0.17743702 | F23: =(F22/E22)-1 -> 0.34063953 | G23: =(G22/F22)-1 -> 0.11388178 | H23: =(H22/G22)-1 -> 0.029939653 | I23: 0.0244 | J23: 0.1183 | K23: 0.0881 | L23: 0.05 | M23: =L23+0.005 -> 0.055 | N23: =M23+0.005 -> 0.06
B24: Net Sales/invested capital | C24: =+C22/C14 -> 2.4372274 | D24: =+D22/D14 -> 2.1003111 | E24: =+E22/E14 -> 2.1819104 | F24: =+F22/F14 -> 2.4228816 | G24: =+G22/G14 -> 2.0244016 | H24: =+H22/H14 -> 2.1819388 | I24: =I22/I14 -> 2.1819388 | J24: =J22/J14 -> 2.1819388 | K24: =K22/K14 -> 2.1819388 | L24: =L22/L14 -> 2.1819388 | M24: =M22/M14 -> 2.1819388 | N24: =N22/N14 -> 2.1819388
B25: Cost of sales | C25: =Income!L8 -> -8773 | D25: =Income!M8 -> -7895 | E25: =Income!N8 -> -9156 | F25: =Income!O8 -> -11775 | G25: =Income!P8 -> -13349 | H25: =Income!Q8 -> -13618 | I25: =-I26*I22 -> -13820.734 | J25: =-J26*J22 -> -15455.726 | K25: =(-K26*K22)*0.98 -> -16481.028 | L25: =(-L26*L22)*0.95 -> -16775.332 | M25: =(-M26*M22)*0.9 -> -16766.503 | N25: =(-N26*N22)*0.9 -> -17772.493
B26: Cost of sales/net sales | C26: =-C25/C22 -> 0.5251721 | D26: =-D25/D22 -> 0.54045728 | E26: =-E25/E22 -> 0.53232558 | F26: =-F25/F22 -> 0.5106466 | G26: =-G25/G22 -> 0.51971968 | H26: =-H25/H22 -> 0.51478037 | I26: 0.51 | J26: =I26 -> 0.51 | K26: =J26 -> 0.51 | L26: =K26 -> 0.51 | M26: =L26 -> 0.51 | N26: =M26 -> 0.51
B27: Selling, general & administrative expenses | C27: =Income!L9 -> -971 | D27: =Income!M9 -> -947 | E27: =Income!N9 -> -1076 | F27: =Income!O9 -> -1211 | G27: =Income!P9 -> -1419 | H27: =Income!Q9 -> -1622 | I27: =-I28*I22 -> -1707.2671 | J27: -1806.23 | K27: -1881.24 | L27: =-L28*L$22 -> -2181.3126 | M27: =-M28*M$22 -> -2301.2848 | N27: =-N28*N$22 -> -2439.3619
B28: SG&A/net sales | C28: =-C27/C22 -> 0.058126309 | D28: =-D27/D22 -> 0.064827492 | E28: =-E27/E22 -> 0.06255814 | F28: =-F27/F22 -> 0.052517455 | G28: =-G27/G22 -> 0.055246253 | H28: =-H27/H22 -> 0.061313979 | I28: 0.063 | J28: =I28 -> 0.063 | K28: =J28 -> 0.063 | L28: =K28 -> 0.063 | M28: =L28 -> 0.063 | N28: =M28 -> 0.063
B29: Other expenses | C29: =Income!L10 -> -2021 | D29: =Income!M10 -> -2053 | E29: =Income!N10 -> -2237 | F29: =Income!O10 -> -2481 | G29: =Income!P10 -> -2777 | H29: =Income!Q10 -> -3116 | I29: =-I30*I$22 -> -3197.7384 | J29: =-J30*J$22 -> -3576.0308 | K29: =-K30*K$22 -> -3891.0791 | L29: =-L30*L$22 -> -4085.6331 | M29: =-M30*M$22 -> -4310.3429 | N29: =-N30*N$22 -> -4568.9635
B30: Other expenses/net sales | C30: =-C29/C22 -> 0.12098174 | D30: =-D29/D22 -> 0.14053943 | E30: =-E29/E22 -> 0.13005814 | F30: =-F29/F22 -> 0.10759356 | G30: =-G29/G22 -> 0.10811758 | H30: =-H29/H22 -> 0.11778937 | I30: 0.118 | J30: =I30 -> 0.118 | K30: =J30 -> 0.118 | L30: =K30 -> 0.118 | M30: =L30 -> 0.118 | N30: =M30 -> 0.118
B31: Depreciation & amortization | C31: =Income!L11 -> -457 | D31: =Income!M11 -> -363 | E31: =Income!N11 -> -376 | F31: =Income!O11 -> -394 | G31: =Income!P11 -> -444 | H31: =Income!Q11 -> -515 | I31: =-I32*I22 -> -379.39269 | J31: =-J32*J22 -> -378.81682 | K31: =-K32*K22 -> -412.19058 | L31: =-L32*L22 -> -432.80011 | M31: =-M32*M22 -> -456.60412 | N31: =-N32*N22 -> -484.00037
B32: Depreciation & amortization/net sales | C32: =-C31/C22 -> 0.027357079 | D32: =-D31/D22 -> 0.024849398 | E32: =-E31/E22 -> 0.021860465 | F32: =-F31/F22 -> 0.017086604 | G32: =-G31/G22 -> 0.017286354 | H32: =-H31/H22 -> 0.019467755 | I32: 0.014 | J32: =I32-0.0015 -> 0.0125 | K32: =J32 -> 0.0125 | L32: =K32 -> 0.0125 | M32: =L32 -> 0.0125 | N32: =M32 -> 0.0125
B33: Interest Rate | C33: =Balance!K40 -> 0 | D33: =Balance!L40 -> 0 | E33: =Balance!M40 -> 0 | F33: =Balance!N40 -> 0 | G33: =Balance!O40 -> 0 | H33: =Balance!P40 -> 0 | I33: =H33 -> 0 | J33: =I33 -> 0 | K33: =J33 -> 0 | L33: =K33 -> 0 | M33: =L33 -> 0 | N33: =M33 -> 0
B34: Operating lease interest | C34: =C33*C8 -> 0 | D34: =D33*D8 -> 0 | E34: =E33*E8 -> 0 | F34: =F33*F8 -> 0 | G34: =G33*G8 -> 0 | H34: =H33*H8 -> 0 | I34: =I33*I8 -> 0 | J34: =J33*J8 -> 0 | ... N34: =N33*N8 -> 0
B35: Operating lease interest/net sales | C35: =C34/C22 -> 0 | D35: =D34/D22 -> 0 | E35: =E34/E22 -> 0 | F35: =F34/F22 -> 0 | G35: =G34/G22 -> 0 | H35: =H34/H22 -> 0 | I35: =I34/I22 -> 0 | J35: =J34/J22 -> 0 | ... N35: =N34/N22 -> 0
B36: Adjusted EBIT | C36: =C22+C25+C27+C29+C31+C34 -> 4483 | D36: =D22+D25+D27+D29+D31+D34 -> 3350 | E36: =E22+E25+E27+E29+E31+E34 -> 4355 | F36: =F22+F25+F27+F29+F31+F34 -> 7198 | G36: =G22+G25+G27+G29+G31+G34 -> 7696 | H36: =H22+H25+H27+H29+H31+H34 -> 7583 | I36: =I22+I25+I27+I29+I31+I34 -> 7994.3459 | J36: =J22+J25+J27+J29+J31+J34 -> 9088.5418 | ... N36: =N22+N25+N27+N29+N31+N34 -> 13455.21
B37: Adjusted EBIT/net sales | C37: =+C36/C22 -> 0.26836277 | D37: =+D36/D22 -> 0.2293264 | E37: =+E36/E22 -> 0.25319767 | F37: =+F36/F22 -> 0.31215577 | G37: =+G36/G22 -> 0.29963013 | H37: =+H36/H22 -> 0.28664852 | I37: =+I36/I22 -> 0.295 | J37: =+J36/J22 -> 0.29989896 | ... N37: =+N36/N22 -> 0.3475
B38: Operating cash taxes | C38: =-C39*C36 -> -1384.8758 | D38: =-D39*D36 -> -576.95014 | E38: =-E39*E36 -> -571.81589 | F38: =-F39*F36 -> -938.68468 | G38: =-G39*G36 -> -1087.7094 | H38: =-H39*H36 -> -845.17626 | I38: =-I39*I36 -> -959.32151 | J38: =-J39*J36 -> -1090.625 | ... N38: =-N39*N36 -> -1614.6252
B39: Tax rate | C39: =Income!L16 -> 0.3089172 | D39: =Income!M16 -> 0.17222392 | E39: =Income!N16 -> 0.13130101 | F39: =Income!O16 -> 0.1304091 | G39: =Income!P16 -> 0.14133439 | H39: =Income!Q16 -> 0.11145671 | I39: 0.12 | J39: =I39 -> 0.12 | K39: =J39 -> 0.12 | L39: =K39 -> 0.12 | M39: =L39 -> 0.12 | N39: =M39 -> 0.12
B41: NOPLAT | C41: =C36+C38 -> 3098.1242 | D41: =D36+D38 -> 2773.0499 | E41: =E36+E38 -> 3783.1841 | F41: =F36+F38 -> 6259.3153 | G41: =G36+G38 -> 6608.2906 | H41: =H36+H38 -> 6737.8237 | I41: =I36+I38 -> 7035.0244 | J41: =J36+J38 -> 7997.9168 | ... N41: =N36+N38 -> 11840.585
B42: Growth (NOPLAT) | D42: =+D41/C41-1 -> -0.10492618 | E42: =+E41/D41-1 -> 0.36426833 | F42: =+F41/E41-1 -> 0.65450983 | G42: =+G41/F41-1 -> 0.055752943 | H42: =+H41/G41-1 -> 0.019601617 | I42: =+I41/H41-1 -> 0.044109293 | J42: =+J41/I41-1 -> 0.13687123 | K42: =+K41/J41-1 -> 0.13436335 | ... N42: =+N41/M41-1 -> 0.06
B43: NOPLAT/net sales | C43: =+C41/C22 -> 0.18546089 | D43: =+D41/D22 -> 0.18983091 | E43: =+E41/E22 -> 0.21995256 | F43: =+F41/F22 -> 0.27144782 | G43: =+G41/G22 -> 0.25728209 | H43: =+H41/H22 -> 0.25469962 | I43: =+I41/I22 -> 0.2596 | J43: =+J41/J22 -> 0.26391109 | ... N43: =+N41/N22 -> 0.3058
B44: ROIC | C44: =C41/C14 -> 0.45201036 | D44: =D41/D14 -> 0.39870396 | E44: =E41/E14 -> 0.4799168 | F44: =F41/F14 -> 0.65768592 | G44: =G41/G14 -> 0.52084228 | H44: =H41/H14 -> 0.55573897 | I44: =I41/I14 -> 0.5664313 | J44: =J41/J14 -> 0.57583783 | ... N44: =N41/N14 -> 0.66723687
...

Sheet WACC
A2: Comps data directly pulled from FactSet without modification | B2: Comps
B3: Name | C3: Total Debt/ Total Equity | D3: Beta to Loc Indx 3 Year | E3: Tax Rate | F3: Unlvrd Beta calculated
B4: Applied Materials | C4: 0.354 | D4: 1.82 | E4: 0.116 | F4: =D4/(1+(C4)*(1-(E4))) -> 1.3862062
B5: KLA | C5: 2.025 | D5: 1.75 | E5: 0.134 | F5: =D5/(1+(C5)*(1-(E5))) -> 0.63552013
B6: Lam Research | C6: 0.617 | D6: 1.91 | E6: 0.122 | F6: =D6/(1+(C6)*(1-(E6))) -> 1.2388712
B7: ASML Holding | C7: 0.313 | D7: 2.04 | E7: 0.159 | F7: =D7/(1+(C7)*(1-(E7))) -> 1.614904
B8: GlobalFoundries | C8: 0.245 | D8: 1.87 | E8: 0.056 | F8: =D8/(1+(C8)*(1-(E8))) -> 1.5187447
B9: Onto Innovation | C9: 0.01 | D9: 1.87 | E9: 0.081 | F9: =D9/(1+(C9)*(1-(E9))) -> 1.8529712
B10: Teradyne | C10: 0.029 | D10: 1.7 | E10: 0.14 | F10: =D10/(1+(C10)*(1-(E10))) -> 1.6586337
E18: Average | F18: =AVERAGE(F4:F11) -> 1.4151216
C22: D/E % | E22: Tax % | F22: Levered Beta
A23: AMAT Levered Bata | B23: AMAT Levered Beta based on comps | C23: =C4 -> 0.354 | E23: 0.116 | F23: =F18*(1+(C23)*(1-(E23))) -> 1.8579641
B26: 10 Year Treasury | C26: 0.0375 | E26: Beta | F26: 1.5
A27: Treasury yield is forecasted based on the interest hike forecasting for 2018 & 2019 | B27: 10y Market Premium | C27: 0.05 | E27: 10y Ke | F27: =$C$26+F26*$C$27 -> 0.1125 | G27: =F26+0.1 -> 1.6 | H27: =G27+0.1 -> 1.7 | I27: =H27+0.1 -> 1.8 | J27: =I27+0.1 -> 1.9
G28: =$C$26+G27*$C$27 -> 0.1175 | H28: =$C$26+H27*$C$27 -> 0.1225 | I28: =$C$26+I27*$C$27 -> 0.1275 | J28: =$C$26+J27*$C$27 -> 0.1325
C30: =4.15-3.64 -> 0.51
B33: 10y Semi Cond-company A rating spread | C33: 0.0077 | D33: 0.0077 | E33: 0.0077 | F33: 0.0077 | G33: 0.0077
A34: WACC calculation | B34: Kd (10y T rate + spread) | C34: =C26+C33 -> 0.0452 | D34: =C34 -> 0.0452 | E34: =D34 -> 0.0452 | F34: =E34 -> 0.0452 | G34: =F34 -> 0.0452
B35: 10y Ke | C35: =F27 -> 0.1125 | D35: =G28 -> 0.1175 | E35: =H28 -> 0.1225 | F35: =I28 -> 0.1275 | G35: =J28 -> 0.1325
B36: Weight d | C36: =1-C37 -> 0.26144756 | D36: =C36 -> 0.26144756 | E36: =D36 -> 0.26144756 | F36: =E36 -> 0.26144756 | G36: =F36 -> 0.26144756
B37: Weight e | C37: =1/(1+C4) -> 0.73855244 | D37: =C37 -> 0.73855244 | E37: =D37 -> 0.73855244 | F37: =E37 -> 0.73855244 | G37: =F37 -> 0.73855244
B38: Tax | C38: =E4 -> 0.116 | D38: =C38 -> 0.116 | E38: =D38 -> 0.116 | F38: =E38 -> 0.116 | G38: =F38 -> 0.116 | H38: Average
B39: WACC (10y) | C39: =C34*(1-C38)*C36+C37*C35 -> 0.093533757 | D39: =D34*(1-D38)*D36+D37*D35 -> 0.097226519 | E39: =E34*(1-E38)*E36+E37*E35 -> 0.10091928 | F39: =F34*(1-F38)*F36+F37*F35 -> 0.10461204 | G39: =G34*(1-G38)*G36+G37*G35 -> 0.10830481 | H39: =AVERAGE(C39:G39) -> 0.10091928
B49: C34 credit spread obtained from Capital IQ

Sheet Valuation
C2: Valued as of 10/29/23 | G2: 1 | H2: 2 | I2: 3 | J2: 4 | K2: 5 | L2: 6
F3: FCF | G3: 6890.75 | H3: 7307.64 | I3: 8928.47 | J3: 8797.18 | K3: =Forecast!M45 -> 10297.598 | L3: =Forecast!N45 -> 10836.111
C5: All in million, except per share data | F5: Value of Operations
C6: WACC | D6: 0.1055 | F6: WACC | G6: Perpetual Growth
C7: Growth | D7: =J7 -> 0.045 | G7: 0.03 | H7: =G7+0.5% -> 0.035 | I7: =H7+0.5% -> 0.04 | J7: =I7+0.5% -> 0.045 | K7: =J7+0.5% -> 0.05 | L7: =K7+0.5% -> 0.055 | M7: =L7+0.5% -> 0.06
C8: PV Of Operations | D8: =$G$3/(1+$F14)+$H$3/(1+$F14)^2+$I$3/(1+$F14)^3+$J$3/(1+$F14)^4+$K$3/(1+$F14)^5+(1/(1+$F14)^5)*($L$3/($F14-J$7)) -> 153748.42 | F8: 0.07 | G8: =(($G$3/(1+$F8)+$H$3/(1+$F8)^2+$I$3/(1+$F8)^3+$J$3/(1+$F8)^4+$K$3/(1+$F8)^5+(1/(1+$F8)^5)*($L$3/($F8-G$7)))+($D$9+$D$11))/$D$14 -> 278.89594 | H8: =(($G$3/(1+$F8)+$H$3/(1+$F8)^2+$I$3/(1+$F8)^3+$J$3/(1+$F8)^4+$K$3/(1+$F8)^5+(1/(1+$F8)^5)*($L$3/($F8-H$7)))+($D$9+$D$11))/$D$14 -> 312.38241 | I8: =(($G$3/(1+$F8)+$H$3/(1+$F8)^2+$I$3/(1+$F8)^3+$J$3/(1+$F8)^4+$K$3/(1+$F8)^5+(1/(1+$F8)^5)*($L$3/($F8-I$7)))+($D$9+$D$11))/$D$14 -> 357.03103 | J8: =(($G$3/(1+$F8)+$H$3/(1+$F8)^2+$I$3/(1+$F8)^3+$J$3/(1+$F8)^4+$K$3/(1+$F8)^5+(1/(1+$F8)^5)*($L$3/($F8-J$7)))+($D$9+$D$11))/$D$14 -> 419.5391 | K8: =(($G$3/(1+$F8)+$H$3/(1+$F8)^2+$I$3/(1+$F8)^3+$J$3/(1+$F8)^4+$K$3/(1+$F8)^5+(1/(1+$F8)^5)*($L$3/($F8-K$7)))+($D$9+$D$11))/$D$14 -> 513.30121 | L8: =(($G$3/(1+$F8)+$H$3/(1+$F8)^2+$I$3/(1+$F8)^3+$J$3/(1+$F8)^4+$K$3/(1+$F8)^5+(1/(1+$F8)^5)*($L$3/($F8-L$7)))+($D$9+$D$11))/$D$14 -> 669.57139 | M8: =(($G$3/(1+$F8)+$H$3/(1+$F8)^2+$I$3/(1+$F8)^3+$J$3/(1+$F8)^4+$K$3/(1+$F8)^5+(1/(1+$F8)^5)*($L$3/($F8-M$7)))+($D$9+$D$11))/$D$14 -> 982.11175
C9: NOA | D9: =Balance!P25 -> 8620.92 | F9: =F8+0.5% -> 0.075 | G9: =(($G$3/(1+$F9)+$H$3/(1+$F9)^2+$I$3/(1+$F9)^3+$J$3/(1+$F9)^4+$K$3/(1+$F9)^5+(1/(1+$F9)^5)*($L$3/($F9-G$7)))+($D$9+$D$11))/$D$14 -> 247.46333 | H9: =(($G$3/(1+$F9)+$H$3/(1+$F9)^2+$I$3/(1+$F9)^3+$J$3/(1+$F9)^4+$K$3/(1+$F9)^5+(1/(1+$F9)^5)*($L$3/($F9-H$7)))+($D$9+$D$11))/$D$14 -> 272.90827 | I9: =(($G$3/(1+$F9)+$H$3/(1+$F9)^2+$I$3/(1+$F9)^3+$J$3/(1+$F9)^4+$K$3/(1+$F9)^5+(1/(1+$F9)^5)*($L$3/($F9-I$7)))+($D$9+$D$11))/$D$14 -> 305.62319 | J9: =(($G$3/(1+$F9)+$H$3/(1+$F9)^2+$I$3/(1+$F9)^3+$J$3/(1+$F9)^4+$K$3/(1+$F9)^5+(1/(1+$F9)^5)*($L$3/($F9-J$7)))+($D$9+$D$11))/$D$14 -> 349.24309 | K9: =(($G$3/(1+$F9)+$H$3/(1+$F9)^2+$I$3/(1+$F9)^3+$J$3/(1+$F9)^4+$K$3/(1+$F9)^5+(1/(1+$F9)^5)*($L$3/($F9-K$7)))+($D$9+$D$11))/$D$14 -> 410.31094 | L9: =(($G$3/(1+$F9)+$H$3/(1+$F9)^2+$I$3/(1+$F9)^3+$J$3/(1+$F9)^4+$K$3/(1+$F9)^5+(1/(1+$F9)^5)*($L$3/($F9-L$7)))+($D$9+$D$11))/$D$14 -> 501.91273 | M9: =(($G$3/(1+$F9)+$H$3/(1+$F9)^2+$I$3/(1+$F9)^3+$J$3/(1+$F9)^4+$K$3/(1+$F9)^5+(1/(1+$F9)^5)*($L$3/($F9-M$7)))+($D$9+$D$11))/$D$14 -> 654.58237
C10: Firm Value | D10: =SUM(D8:D9) -> 162369.34 | F10: =F9+0.5% -> 0.08 | G10: =(($G$3/(1+$F10)+$H$3/(1+$F10)^2+$I$3/(1+$F10)^3+$J$3/(1+$F10)^4+$K$3/(1+$F10)^5+(1/(1+$F10)^5)*($L$3/($F10-G$7)))+($D$9+$D$11))/$D$14 -> 222.33149 | H10: =(($G$3/(1+$F10)+$H$3/(1+$F10)^2+$I$3/(1+$F10)^3+$J$3/(1+$F10)^4+$K$3/(1+$F10)^5+(1/(1+$F10)^5)*($L$3/($F10-H$7)))+($D$9+$D$11))/$D$14 -> 242.22058 | I10: =(($G$3/(1+$F10)+$H$3/(1+$F10)^2+$I$3/(1+$F10)^3+$J$3/(1+$F10)^4+$K$3/(1+$F10)^5+(1/(1+$F10)^5)*($L$3/($F10-I$7)))+($D$9+$D$11))/$D$14 -> 267.08194 | J10: =(($G$3/(1+$F10)+$H$3/(1+$F10)^2+$I$3/(1+$F10)^3+$J$3/(1+$F10)^4+$K$3/(1+$F10)^5+(1/(1+$F10)^5)*($L$3/($F10-J$7)))+($D$9+$D$11))/$D$14 -> 299.04656 | K10: =(($G$3/(1+$F10)+$H$3/(1+$F10)^2+$I$3/(1+$F10)^3+$J$3/(1+$F10)^4+$K$3/(1+$F10)^5+(1/(1+$F10)^5)*($L$3/($F10-K$7)))+($D$9+$D$11))/$D$14 -> 341.66604 | L10: =(($G$3/(1+$F10)+$H$3/(1+$F10)^2+$I$3/(1+$F10)^3+$J$3/(1+$F10)^4+$K$3/(1+$F10)^5+(1/(1+$F10)^5)*($L$3/($F10-L$7)))+($D$9+$D$11))/$D$14 -> 401.33331 | M10: =(($G$3/(1+$F10)+$H$3/(1+$F10)^2+$I$3/(1+$F10)^3+$J$3/(1+$F10)^4+$K$3/(1+$F10)^5+(1/(1+$F10)^5)*($L$3/($F10-M$7)))+($D$9+$D$11))/$D$14 -> 490.83423
C11: DDE | D11: =-Balance!P32 -> -6125 | F11: =F10+0.5% -> 0.085 | G11: =(($G$3/(1+$F11)+$H$3/(1+$F11)^2+$I$3/(1+$F11)^3+$J$3/(1+$F11)^4+$K$3/(1+$F11)^5+(1/(1+$F11)^5)*($L$3/($F11-G$7)))+($D$9+$D$11))/$D$14 -> 201.78168 | H11: =(($G$3/(1+$F11)+$H$3/(1+$F11)^2+$I$3/(1+$F11)^3+$J$3/(1+$F11)^4+$K$3/(1+$F11)^5+(1/(1+$F11)^5)*($L$3/($F11-H$7)))+($D$9+$D$11))/$D$14 -> 217.68306 | I11: =(($G$3/(1+$F11)+$H$3/(1+$F11)^2+$I$3/(1+$F11)^3+$J$3/(1+$F11)^4+$K$3/(1+$F11)^5+(1/(1+$F11)^5)*($L$3/($F11-I$7)))+($D$9+$D$11))/$D$14 -> 237.11808 | J11: =(($G$3/(1+$F11)+$H$3/(1+$F11)^2+$I$3/(1+$F11)^3+$J$3/(1+$F11)^4+$K$3/(1+$F11)^5+(1/(1+$F11)^5)*($L$3/($F11-J$7)))+($D$9+$D$11))/$D$14 -> 261.41186 | K11: =(($G$3/(1+$F11)+$H$3/(1+$F11)^2+$I$3/(1+$F11)^3+$J$3/(1+$F11)^4+$K$3/(1+$F11)^5+(1/(1+$F11)^5)*($L$3/($F11-K$7)))+($D$9+$D$11))/$D$14 -> 292.64672 | L11: =(($G$3/(1+$F11)+$H$3/(1+$F11)^2+$I$3/(1+$F11)^3+$J$3/(1+$F11)^4+$K$3/(1+$F11)^5+(1/(1+$F11)^5)*($L$3/($F11-L$7)))+($D$9+$D$11))/$D$14 -> 334.2932 | M11: =(($G$3/(1+$F11)+$H$3/(1+$F11)^2+$I$3/(1+$F11)^3+$J$3/(1+$F11)^4+$K$3/(1+$F11)^5+(1/(1+$F11)^5)*($L$3/($F11-M$7)))+($D$9+$D$11))/$D$14 -> 392.59826
C12: Equity Value | D12: =SUM(D10:D11) -> 156244.34 | F12: =F11+0.5% -> 0.09 | G12: =(($G$3/(1+$F12)+$H$3/(1+$F12)^2+$I$3/(1+$F12)^3+$J$3/(1+$F12)^4+$K$3/(1+$F12)^5+(1/(1+$F12)^5)*($L$3/($F12-G$7)))+($D$9+$D$11))/$D$14 -> 184.6681 | H12: =(($G$3/(1+$F12)+$H$3/(1+$F12)^2+$I$3/(1+$F12)^3+$J$3/(1+$F12)^4+$K$3/(1+$F12)^5+(1/(1+$F12)^5)*($L$3/($F12-H$7)))+($D$9+$D$11))/$D$14 -> 197.6181 | I12: =(($G$3/(1+$F12)+$H$3/(1+$F12)^2+$I$3/(1+$F12)^3+$J$3/(1+$F12)^4+$K$3/(1+$F12)^5+(1/(1+$F12)^5)*($L$3/($F12-I$7)))+($D$9+$D$11))/$D$14 -> 213.1581 | J12: =(($G$3/(1+$F12)+$H$3/(1+$F12)^2+$I$3/(1+$F12)^3+$J$3/(1+$F12)^4+$K$3/(1+$F12)^5+(1/(1+$F12)^5)*($L$3/($F12-J$7)))+($D$9+$D$11))/$D$14 -> 232.15144 | K12: =(($G$3/(1+$F12)+$H$3/(1+$F12)^2+$I$3/(1+$F12)^3+$J$3/(1+$F12)^4+$K$3/(1+$F12)^5+(1/(1+$F12)^5)*($L$3/($F12-K$7)))+($D$9+$D$11))/$D$14 -> 255.89311 | L12: =(($G$3/(1+$F12)+$H$3/(1+$F12)^2+$I$3/(1+$F12)^3+$J$3/(1+$F12)^4+$K$3/(1+$F12)^5+(1/(1+$F12)^5)*($L$3/($F12-L$7)))+($D$9+$D$11))/$D$14 -> 286.41811 | M12: =(($G$3/(1+$F12)+$H$3/(1+$F12)^2+$I$3/(1+$F12)^3+$J$3/(1+$F12)^4+$K$3/(1+$F12)^5+(1/(1+$F12)^5)*($L$3/($F12-M$7)))+($D$9+$D$11))/$D$14 -> 327.11812
F13: =F12+0.5% -> 0.095 | G13: =(($G$3/(1+$F13)+$H$3/(1+$F13)^2+$I$3/(1+$F13)^3+$J$3/(1+$F13)^4+$K$3/(1+$F13)^5+(1/(1+$F13)^5)*($L$3/($F13-G$7)))+($D$9+$D$11))/$D$14 -> 170.1975 | H13: =(($G$3/(1+$F13)+$H$3/(1+$F13)^2+$I$3/(1+$F13)^3+$J$3/(1+$F13)^4+$K$3/(1+$F13)^5+(1/(1+$F13)^5)*($L$3/($F13-H$7)))+($D$9+$D$11))/$D$14 -> 180.90729 | I13: =(($G$3/(1+$F13)+$H$3/(1+$F13)^2+$I$3/(1+$F13)^3+$J$3/(1+$F13)^4+$K$3/(1+$F13)^5+(1/(1+$F13)^5)*($L$3/($F13-I$7)))+($D$9+$D$11))/$D$14 -> 193.56432 | J13: =(($G$3/(1+$F13)+$H$3/(1+$F13)^2+$I$3/(1+$F13)^3+$J$3/(1+$F13)^4+$K$3/(1+$F13)^5+(1/(1+$F13)^5)*($L$3/($F13-J$7)))+($D$9+$D$11))/$D$14 -> 208.75275 | K13: =(($G$3/(1+$F13)+$H$3/(1+$F13)^2+$I$3/(1+$F13)^3+$J$3/(1+$F13)^4+$K$3/(1+$F13)^5+(1/(1+$F13)^5)*($L$3/($F13-K$7)))+($D$9+$D$11))/$D$14 -> 227.31639 | L13: =(($G$3/(1+$F13)+$H$3/(1+$F13)^2+$I$3/(1+$F13)^3+$J$3/(1+$F13)^4+$K$3/(1+$F13)^5+(1/(1+$F13)^5)*($L$3/($F13-L$7)))+($D$9+$D$11))/$D$14 -> 250.52094 | M13: =(($G$3/(1+$F13)+$H$3/(1+$F13)^2+$I$3/(1+$F13)^3+$J$3/(1+$F13)^4+$K$3/(1+$F13)^5+(1/(1+$F13)^5)*($L$3/($F13-M$7)))+($D$9+$D$11))/$D$14 -> 280.35536
C14: Outstanding Shares | D14: 824 | F14: =F13+0.5% -> 0.1 | G14: =(($G$3/(1+$F14)+$H$3/(1+$F14)^2+$I$3/(1+$F14)^3+$J$3/(1+$F14)^4+$K$3/(1+$F14)^5+(1/(1+$F14)^5)*($L$3/($F14-G$7)))+($D$9+$D$11))/$D$14 -> 157.80328 | H14: =(($G$3/(1+$F14)+$H$3/(1+$F14)^2+$I$3/(1+$F14)^3+$J$3/(1+$F14)^4+$K$3/(1+$F14)^5+(1/(1+$F14)^5)*($L$3/($F14-H$7)))+($D$9+$D$11))/$D$14 -> 166.77636 | I14: =(($G$3/(1+$F14)+$H$3/(1+$F14)^2+$I$3/(1+$F14)^3+$J$3/(1+$F14)^4+$K$3/(1+$F14)^5+(1/(1+$F14)^5)*($L$3/($F14-I$7)))+($D$9+$D$11))/$D$14 -> 177.24495 | J14: =(($G$3/(1+$F14)+$H$3/(1+$F14)^2+$I$3/(1+$F14)^3+$J$3/(1+$F14)^4+$K$3/(1+$F14)^5+(1/(1+$F14)^5)*($L$3/($F14-J$7)))+($D$9+$D$11))/$D$14 -> 189.61692 | K14: =(($G$3/(1+$F14)+$H$3/(1+$F14)^2+$I$3/(1+$F14)^3+$J$3/(1+$F14)^4+$K$3/(1+$F14)^5+(1/(1+$F14)^5)*($L$3/($F14-K$7)))+($D$9+$D$11))/$D$14 -> 204.46328 | L14: =(($G$3/(1+$F14)+$H$3/(1+$F14)^2+$I$3/(1+$F14)^3+$J$3/(1+$F14)^4+$K$3/(1+$F14)^5+(1/(1+$F14)^5)*($L$3/($F14-L$7)))+($D$9+$D$11))/$D$14 -> 222.60884 | M14: =(($G$3/(1+$F14)+$H$3/(1+$F14)^2+$I$3/(1+$F14)^3+$J$3/(1+$F14)^4+$K$3/(1+$F14)^5+(1/(1+$F14)^5)*($L$3/($F14-M$7)))+($D$9+$D$11))/$D$14 -> 245.29079
C15: Share Price | D15: =D12/D14 -> 189.61692 | F15: =F14+0.5% -> 0.105 | G15: =(($G$3/(1+$F15)+$H$3/(1+$F15)^2+$I$3/(1+$F15)^3+$J$3/(1+$F15)^4+$K$3/(1+$F15)^5+(1/(1+$F15)^5)*($L$3/($F15-G$7)))+($D$9+$D$11))/$D$14 -> 147.06995 | H15: =(($G$3/(1+$F15)+$H$3/(1+$F15)^2+$I$3/(1+$F15)^3+$J$3/(1+$F15)^4+$K$3/(1+$F15)^5+(1/(1+$F15)^5)*($L$3/($F15-H$7)))+($D$9+$D$11))/$D$14 -> 154.67226 | I15: =(($G$3/(1+$F15)+$H$3/(1+$F15)^2+$I$3/(1+$F15)^3+$J$3/(1+$F15)^4+$K$3/(1+$F15)^5+(1/(1+$F15)^5)*($L$3/($F15-I$7)))+($D$9+$D$11))/$D$14 -> 163.44415 | J15: =(($G$3/(1+$F15)+$H$3/(1+$F15)^2+$I$3/(1+$F15)^3+$J$3/(1+$F15)^4+$K$3/(1+$F15)^5+(1/(1+$F15)^5)*($L$3/($F15-J$7)))+($D$9+$D$11))/$D$14 -> 173.67803 | K15: =(($G$3/(1+$F15)+$H$3/(1+$F15)^2+$I$3/(1+$F15)^3+$J$3/(1+$F15)^4+$K$3/(1+$F15)^5+(1/(1+$F15)^5)*($L$3/($F15-K$7)))+($D$9+$D$11))/$D$14 -> 185.77262 | L15: =(($G$3/(1+$F15)+$H$3/(1+$F15)^2+$I$3/(1+$F15)^3+$J$3/(1+$F15)^4+$K$3/(1+$F15)^5+(1/(1+$F15)^5)*($L$3/($F15-L$7)))+($D$9+$D$11))/$D$14 -> 200.28612 | M15: =(($G$3/(1+$F15)+$H$3/(1+$F15)^2+$I$3/(1+$F15)^3+$J$3/(1+$F15)^4+$K$3/(1+$F15)^5+(1/(1+$F15)^5)*($L$3/($F15-M$7)))+($D$9+$D$11))/$D$14 -> 218.02484
F16: =F15+0.5% -> 0.11 | G16: =(($G$3/(1+$F16)+$H$3/(1+$F16)^2+$I$3/(1+$F16)^3+$J$3/(1+$F16)^4+$K$3/(1+$F16)^5+(1/(1+$F16)^5)*($L$3/($F16-G$7)))+($D$9+$D$11))/$D$14 -> 137.68589 | H16: =(($G$3/(1+$F16)+$H$3/(1+$F16)^2+$I$3/(1+$F16)^3+$J$3/(1+$F16)^4+$K$3/(1+$F16)^5+(1/(1+$F16)^5)*($L$3/($F16-H$7)))+($D$9+$D$11))/$D$14 -> 144.18944 | I16: =(($G$3/(1+$F16)+$H$3/(1+$F16)^2+$I$3/(1+$F16)^3+$J$3/(1+$F16)^4+$K$3/(1+$F16)^5+(1/(1+$F16)^5)*($L$3/($F16-I$7)))+($D$9+$D$11))/$D$14 -> 151.62206 | J16: =(($G$3/(1+$F16)+$H$3/(1+$F16)^2+$I$3/(1+$F16)^3+$J$3/(1+$F16)^4+$K$3/(1+$F16)^5+(1/(1+$F16)^5)*($L$3/($F16-J$7)))+($D$9+$D$11))/$D$14 -> 160.19816 | K16: =(($G$3/(1+$F16)+$H$3/(1+$F16)^2+$I$3/(1+$F16)^3+$J$3/(1+$F16)^4+$K$3/(1+$F16)^5+(1/(1+$F16)^5)*($L$3/($F16-K$7)))+($D$9+$D$11))/$D$14 -> 170.20361 | L16: =(($G$3/(1+$F16)+$H$3/(1+$F16)^2+$I$3/(1+$F16)^3+$J$3/(1+$F16)^4+$K$3/(1+$F16)^5+(1/(1+$F16)^5)*($L$3/($F16-L$7)))+($D$9+$D$11))/$D$14 -> 182.02824 | M16: =(($G$3/(1+$F16)+$H$3/(1+$F16)^2+$I$3/(1+$F16)^3+$J$3/(1+$F16)^4+$K$3/(1+$F16)^5+(1/(1+$F16)^5)*($L$3/($F16-M$7)))+($D$9+$D$11))/$D$14 -> 196.21779
C17: NOA/Share | D17: =D9/D14 -> 10.462282 | F17: =F16+0.5% -> 0.115 | G17: =(($G$3/(1+$F17)+$H$3/(1+$F17)^2+$I$3/(1+$F17)^3+$J$3/(1+$F17)^4+$K$3/(1+$F17)^5+(1/(1+$F17)^5)*($L$3/($F17-G$7)))+($D$9+$D$11))/$D$14 -> 129.41282 | H17: =(($G$3/(1+$F17)+$H$3/(1+$F17)^2+$I$3/(1+$F17)^3+$J$3/(1+$F17)^4+$K$3/(1+$F17)^5+(1/(1+$F17)^5)*($L$3/($F17-H$7)))+($D$9+$D$11))/$D$14 -> 135.02372 | I17: =(($G$3/(1+$F17)+$H$3/(1+$F17)^2+$I$3/(1+$F17)^3+$J$3/(1+$F17)^4+$K$3/(1+$F17)^5+(1/(1+$F17)^5)*($L$3/($F17-I$7)))+($D$9+$D$11))/$D$14 -> 141.38275 | J17: =(($G$3/(1+$F17)+$H$3/(1+$F17)^2+$I$3/(1+$F17)^3+$J$3/(1+$F17)^4+$K$3/(1+$F17)^5+(1/(1+$F17)^5)*($L$3/($F17-J$7)))+($D$9+$D$11))/$D$14 -> 148.65021 | K17: =(($G$3/(1+$F17)+$H$3/(1+$F17)^2+$I$3/(1+$F17)^3+$J$3/(1+$F17)^4+$K$3/(1+$F17)^5+(1/(1+$F17)^5)*($L$3/($F17-K$7)))+($D$9+$D$11))/$D$14 -> 157.03574 | L17: =(($G$3/(1+$F17)+$H$3/(1+$F17)^2+$I$3/(1+$F17)^3+$J$3/(1+$F17)^4+$K$3/(1+$F17)^5+(1/(1+$F17)^5)*($L$3/($F17-L$7)))+($D$9+$D$11))/$D$14 -> 166.81886 | M17: =(($G$3/(1+$F17)+$H$3/(1+$F17)^2+$I$3/(1+$F17)^3+$J$3/(1+$F17)^4+$K$3/(1+$F17)^5+(1/(1+$F17)^5)*($L$3/($F17-M$7)))+($D$9+$D$11))/$D$14 -> 178.38073
F18: =F17+0.5% -> 0.12 | G18: =(($G$3/(1+$F18)+$H$3/(1+$F18)^2+$I$3/(1+$F18)^3+$J$3/(1+$F18)^4+$K$3/(1+$F18)^5+(1/(1+$F18)^5)*($L$3/($F18-G$7)))+($D$9+$D$11))/$D$14 -> 122.0654 | H18: =(($G$3/(1+$F18)+$H$3/(1+$F18)^2+$I$3/(1+$F18)^3+$J$3/(1+$F18)^4+$K$3/(1+$F18)^5+(1/(1+$F18)^5)*($L$3/($F18-H$7)))+($D$9+$D$11))/$D$14 -> 126.94253 | I18: =(($G$3/(1+$F18)+$H$3/(1+$F18)^2+$I$3/(1+$F18)^3+$J$3/(1+$F18)^4+$K$3/(1+$F18)^5+(1/(1+$F18)^5)*($L$3/($F18-I$7)))+($D$9+$D$11))/$D$14 -> 132.42931 | J18: =(($G$3/(1+$F18)+$H$3/(1+$F18)^2+$I$3/(1+$F18)^3+$J$3/(1+$F18)^4+$K$3/(1+$F18)^5+(1/(1+$F18)^5)*($L$3/($F18-J$7)))+($D$9+$D$11))/$D$14 -> 138.64765 | K18: =(($G$3/(1+$F18)+$H$3/(1+$F18)^2+$I$3/(1+$F18)^3+$J$3/(1+$F18)^4+$K$3/(1+$F18)^5+(1/(1+$F18)^5)*($L$3/($F18-K$7)))+($D$9+$D$11))/$D$14 -> 145.75433 | L18: =(($G$3/(1+$F18)+$H$3/(1+$F18)^2+$I$3/(1+$F18)^3+$J$3/(1+$F18)^4+$K$3/(1+$F18)^5+(1/(1+$F18)^5)*($L$3/($F18-L$7)))+($D$9+$D$11))/$D$14 -> 153.95435 | M18: =(($G$3/(1+$F18)+$H$3/(1+$F18)^2+$I$3/(1+$F18)^3+$J$3/(1+$F18)^4+$K$3/(1+$F18)^5+(1/(1+$F18)^5)*($L$3/($F18-M$7)))+($D$9+$D$11))/$D$14 -> 163.52104
F19: =F18+0.5% -> 0.125 | G19: =(($G$3/(1+$F19)+$H$3/(1+$F19)^2+$I$3/(1+$F19)^3+$J$3/(1+$F19)^4+$K$3/(1+$F19)^5+(1/(1+$F19)^5)*($L$3/($F19-G$7)))+($D$9+$D$11))/$D$14 -> 115.49732 | H19: =(($G$3/(1+$F19)+$H$3/(1+$F19)^2+$I$3/(1+$F19)^3+$J$3/(1+$F19)^4+$K$3/(1+$F19)^5+(1/(1+$F19)^5)*($L$3/($F19-H$7)))+($D$9+$D$11))/$D$14 -> 119.76496 | I19: =(($G$3/(1+$F19)+$H$3/(1+$F19)^2+$I$3/(1+$F19)^3+$J$3/(1+$F19)^4+$K$3/(1+$F19)^5+(1/(1+$F19)^5)*($L$3/($F19-I$7)))+($D$9+$D$11))/$D$14 -> 124.53467 | J19: =(($G$3/(1+$F19)+$H$3/(1+$F19)^2+$I$3/(1+$F19)^3+$J$3/(1+$F19)^4+$K$3/(1+$F19)^5+(1/(1+$F19)^5)*($L$3/($F19-J$7)))+($D$9+$D$11))/$D$14 -> 129.9006 | K19: =(($G$3/(1+$F19)+$H$3/(1+$F19)^2+$I$3/(1+$F19)^3+$J$3/(1+$F19)^4+$K$3/(1+$F19)^5+(1/(1+$F19)^5)*($L$3/($F19-K$7)))+($D$9+$D$11))/$D$14 -> 135.98198 | L19: =(($G$3/(1+$F19)+$H$3/(1+$F19)^2+$I$3/(1+$F19)^3+$J$3/(1+$F19)^4+$K$3/(1+$F19)^5+(1/(1+$F19)^5)*($L$3/($F19-L$7)))+($D$9+$D$11))/$D$14 -> 142.93213 | M19: =(($G$3/(1+$F19)+$H$3/(1+$F19)^2+$I$3/(1+$F19)^3+$J$3/(1+$F19)^4+$K$3/(1+$F19)^5+(1/(1+$F19)^5)*($L$3/($F19-M$7)))+($D$9+$D$11))/$D$14 -> 150.95154
F20: =F19+0.5% -> 0.13 | G20: =(($G$3/(1+$F20)+$H$3/(1+$F20)^2+$I$3/(1+$F20)^3+$J$3/(1+$F20)^4+$K$3/(1+$F20)^5+(1/(1+$F20)^5)*($L$3/($F20-G$7)))+($D$9+$D$11))/$D$14 -> 109.59154 | H20: =(($G$3/(1+$F20)+$H$3/(1+$F20)^2+$I$3/(1+$F20)^3+$J$3/(1+$F20)^4+$K$3/(1+$F20)^5+(1/(1+$F20)^5)*($L$3/($F20-H$7)))+($D$9+$D$11))/$D$14 -> 113.34819 | I20: =(($G$3/(1+$F20)+$H$3/(1+$F20)^2+$I$3/(1+$F20)^3+$J$3/(1+$F20)^4+$K$3/(1+$F20)^5+(1/(1+$F20)^5)*($L$3/($F20-I$7)))+($D$9+$D$11))/$D$14 -> 117.52224 | J20: =(($G$3/(1+$F20)+$H$3/(1+$F20)^2+$I$3/(1+$F20)^3+$J$3/(1+$F20)^4+$K$3/(1+$F20)^5+(1/(1+$F20)^5)*($L$3/($F20-J$7)))+($D$9+$D$11))/$D$14 -> 122.18736 | K20: =(($G$3/(1+$F20)+$H$3/(1+$F20)^2+$I$3/(1+$F20)^3+$J$3/(1+$F20)^4+$K$3/(1+$F20)^5+(1/(1+$F20)^5)*($L$3/($F20-K$7)))+($D$9+$D$11))/$D$14 -> 127.43562 | L20: =(($G$3/(1+$F20)+$H$3/(1+$F20)^2+$I$3/(1+$F20)^3+$J$3/(1+$F20)^4+$K$3/(1+$F20)^5+(1/(1+$F20)^5)*($L$3/($F20-L$7)))+($D$9+$D$11))/$D$14 -> 133.38364 | M20: =(($G$3/(1+$F20)+$H$3/(1+$F20)^2+$I$3/(1+$F20)^3+$J$3/(1+$F20)^4+$K$3/(1+$F20)^5+(1/(1+$F20)^5)*($L$3/($F20-M$7)))+($D$9+$D$11))/$D$14 -> 140.18139

Sheet Multiples
A1: Multiples
D2: Price | H2: Price to
A3: Company | C3: Fiscal | D3: to Sales | F3: PEG | H3: FCF | I3: EV/ | J3: EV/ | K3: EV/
A4: Name | B4: Ticker | C4: Period | D4: Actual (x) | E4: P/E (x) | F4: Ratio (x) | G4: P/BV (x) | H4: Actual (x) | I4: EBITDA (x) | J4: EBIT (x) | K4: Sales (x)
A5: Applied Materials | B5: AMAT-US | C5: 07/28/2024 | D5: 5.826682 | E5: 21.079247 | F5: 1.767723 | G5: 8.208159 | H5: 23.801088 | I5: 18.591635 | J5: 19.576813 | K5: 5.675867
A6: KLA | B6: KLAC-US | C6: 06/2024 | D6: 10.239882 | E6: 36.311279 | F6: 2.005942 | G6: 29.388641 | H6: 33.08538 | I6: 23.980804 | J6: 26.500935 | K6: 10.343838
A7: Lam Research | B7: LRCX-US | C7: 06/2024 | D7: 6.716649 | E7: 26.154679 | F7: 1.464351 | G7: 11.58002 | H7: 23.525301 | I7: 20.902159 | J7: 22.640347 | K7: 6.570125
A8: ASML Holding | B8: ASML-NL | C8: 06/30/2024 | D8: 11.454778 | E8: 43.204024 | F8: 1.948975 | G8: 19.982509 | H8: 98.376922 | I8: 34.243801 | J8: 37.888432 | K8: 11.615904
A9: Veeco Instruments | B9: VECO-US | C9: 06/30/2024 | D9: 2.723668 | E9: 21.866056 | F9: - | G9: 2.426518 | H9: 67.486037 | I9: 16.598087 | J9: 20.832699 | K9: 2.486048
A10: Axcelis Technologies | B10: ACLS-US | C10: 06/30/2024 | D10: 2.914752 | E10: 13.619519 | F10: 1.279899 | G10: 3.448873 | H10: 21.201523 | I10: 10.016092 | J10: 10.572469 | K10: 2.473858
A11: ACM Research A | B11: ACMR-US | C11: 06/30/2024 | D11: 1.582755 | E11: 13.020999 | F11: 0.517628 | G11: 1.2265 | H11: - | I11: 7.567059 | J11: 8.128953 | K11: 1.399112
A12: PDF Solutions | B12: PDFS-US | C12: 06/30/2024 | D12: 6.862665 | E12: - | F12: 1.853333 | G12: 4.832165 | H12: 154.98821 | I12: 226.68208 | J12: - | K12: 6.120359 | M12: Not on WACC tab
A13: Nova | B13: NVMI-US | C13: 06/30/2024 | D13: 10.863557 | E13: 39.525948 | F13: 1.655133 | G13: 6.524097 | H13: 34.726057 | I13: 31.037355 | J13: 34.580173 | K13: 9.274687
A14: Average | D14: 6.576154 | E14: 26.847719 | F14: 1.561623 | G14: 9.735276 | H14: 57.148814 | I14: 43.291008 | J14: 22.590103 | K14: 6.217755
A15: Median | D15: 6.716649 | E15: 24.010368 | F15: 1.711428 | G15: 6.524097 | H15: 33.905718 | I15: 20.902159 | J15: 21.736523 | K15: 6.120359
A16: Currency Dropdown Widget
A18: Top Competitors
D19: Price | H19: Price to
A20: Company | C20: Fiscal | D20: to Sales | F20: PEG | H20: FCF | I20: EV/ | J20: EV/ | K20: EV/
A21: Name | B21: Ticker | C21: Period | D21: Actual (x) | E21: P/E (x) | F21: Ratio (x) | G21: P/BV (x) | H21: Actual (x) | I21: EBITDA (x) | J21: EBIT (x) | K21: Sales (x)
A22: Applied Materials | B22: AMAT-US | C22: 07/28/2024 | D22: 5.826682 | E22: 21.079247 | F22: 1.767723 | G22: 8.208159 | H22: 23.801088 | I22: 18.591635 | J22: 19.576813 | K22: 5.675867
A23: Lam Research | B23: LRCX-US | C23: 06/2024 | D23: 6.716649 | E23: 26.154679 | F23: 1.464351 | G23: 11.58002 | H23: 23.525301 | I23: 20.902159 | J23: 22.640347 | K23: 6.570125
A24: Axcelis Technologies | B24: ACLS-US | C24: 06/30/2024 | D24: 2.914752 | E24: 13.619519 | F24: 1.279899 | G24: 3.448873 | H24: 21.201523 | I24: 10.016092 | J24: 10.572469 | K24: 2.473858
A25: Average | D25: =AVERAGE(D22:D24) -> 5.1526943 | E25: =AVERAGE(E22:E24) -> 20.284482 | F25: =AVERAGE(F22:F24) -> 1.503991 | G25: =AVERAGE(G22:G24) -> 7.745684 | H25: =AVERAGE(H22:H24) -> 22.842637 | I25: =AVERAGE(I22:I24) -> 16.503295 | J25: =AVERAGE(J22:J24) -> 17.596543 | K25: =AVERAGE(K22:K24) -> 4.9066167

Sheet Ratios
A1: Ratios
D2: Total | F2: Total
A3: Company | D3: Asset | E3: Net | F3: Assets
A4: Name | B4: Ticker | C4: ROE (%) | D4: Turnover (x) | E4: Margin (%) | F4: Total Eq (x)
A5: Applied Materials | B5: AMAT-US | C5: 43.910058 | D5: 0.837286 | E5: 27.780885 | F5: 1.785934
A6: KLA | B6: KLAC-US | C6: 87.845433 | D6: 0.663858 | E6: 28.200243 | F6: 4.581966
A7: Lam Research | B7: LRCX-US | C7: 45.705761 | D7: 0.794395 | E7: 25.680462 | F7: 2.195073
A8: ASML Holding | B8: ASML-NL | C8: 53.272028 | D8: 0.655155 | E8: 26.503372 | F8: 2.769387
A9: Veeco Instruments | B9: VECO-US | C9: 12.659563 | D9: 0.569625 | E9: 11.976718 | F9: 1.727402
A10: Axcelis Technologies | B10: ACLS-US | C10: 28.522947 | D10: 0.922358 | E10: 21.542819 | F10: 1.37805
A11: ACM Research A | B11: ACMR-US | C11: 11.149527 | D11: 0.464777 | E11: 12.258763 | F11: 2.001485
A12: PDF Solutions | B12: PDFS-US | C12: -1.215367 | D12: 0.565882 | E12: -1.666006 | F12: 1.283632
A13: Nova | B13: NVMI-US | C13: 20.433918 | D13: 0.49139 | E13: 27.374694 | F13: 1.479919
A14: Average | C14: 33.587096 | D14: 0.662747 | E14: 19.961328 | F14: 2.13365
A15: Median | C15: 28.522947 | D15: 0.655155 | E15: 25.680462 | F15: 1.785934
A16: Currency Dropdown Widget
A19: Dupont Analysis
D20: Total | F20: Total
A21: Company | D21: Asset | E21: Net | F21: Assets
A22: Name | B22: Ticker | C22: ROE (%) | D22: Turnover (x) | E22: Margin (%) | F22: Total Eq (x)
A23: Applied Materials | B23: AMAT-US | C23: 43.910058 | D23: 0.837286 | E23: 27.780885 | F23: 1.785934
A24: Lam Research | B24: LRCX-US | C24: 45.705761 | D24: 0.794395 | E24: 25.680462 | F24: 2.195073
A25: Axcelis Technologies | B25: ACLS-US | C25: 28.522947 | D25: 0.922358 | E25: 21.542819 | F25: 1.37805
A26: average | C26: =AVERAGE(C23:C25) -> 39.379589 | D26: =AVERAGE(D23:D25) -> 0.85134633 | E26: =AVERAGE(E23:E25) -> 25.001389 | F26: =AVERAGE(F23:F25) -> 1.7863523
A28: Valuation
E29: Market Data ($) | I29: Valuation (x) | K29: EV/EBITDA (x) | M29: P/E (x) | O29: P/FCF (x)
A30: Company | C30: Fiscal | E30: Price | F30: Enterprise | G30: Market | H30: Net | I30: Price/ | J30: EV/ | Q30: FCF | R30: Div | S30: Analyst
A31: Name | B31: Ticker | C31: Period | D31: Price | E31: Target | F31: Value | G31: Value | H31: Debt | I31: Sales | J31: Sales | K31: FY1 | L31: FY2 | M31: FY1 | N31: FY2 | O31: FY1 | P31: FY2 | Q31: Yield (%) | R31: Yield (%) | S31: Rating
A32: Applied Materials | B32: AMAT-US | C32: 07/28/2024 | D32: 187.58 | E32: 238.67857 | F32: 153893.1 | G32: 156705.1 | H32: -2432 | I32: 5.826682 | J32: 5.73864 | K32: 18.613887 | L32: 16.142667 | M32: 21.987379 | N32: 19.192108 | O32: 23.354086 | P32: 22.605446 | Q32: 6.844617 | R32: 0.852969 | S32: Overweight (1.40)
A33: KLA | B33: KLAC-US | C33: 06/2024 | D33: 736.40002 | E33: 871.77728 | F33: 102251.88 | G33: 100070.89 | H33: 2315.648 | I33: 10.239882 | J33: 10.440392 | K33: 20.147791 | L33: 17.906226 | M33: 24.665131 | N33: 21.857822 | O33: 24.115273 | P33: 21.330502 | Q33: 2.69949 | R33: 0.787615 | S33: Overweight (1.50)
A34: Lam Research | B34: LRCX-US | C34: 06/2024 | D34: 758.46997 | E34: 1042.5769 | F34: 98356.837 | G34: 99237.332 | H34: -576.806 | I34: 6.716649 | J34: 6.598745 | K34: 17.613055 | L34: 14.105129 | M34: 21.246853 | N34: 16.720057 | O34: 22.211256 | P34: 17.891607 | Q34: 3.027714 | R34: 1.212968 | S34: Overweight (1.39)
A35: ASML Holding | B35: ASML-NL | C35: 06/30/2024 | D35: 800.81683 | E35: 1180.7096 | F35: 314096.09 | G35: 315610.47 | H35: -440.16769 | I35: 11.454778 | J35: 11.417507 | K35: 29.590135 | L35: 19.312956 | M35: 38.160271 | N35: 24.127666 | O35: 60.648697 | P35: 34.127728 | Q35: 1.223787 | R35: 0.857063 | S35: Overweight (1.26)
A36: Veeco Instruments | B36: VECO-US | C36: 06/30/2024 | D36: 30.559999 | E36: 42.857143 | F36: 1834.6009 | G36: 2145.6969 | H36: 8.998 | I36: 2.723668 | J36: 2.614684 | K36: 14.551186 | L36: 12.449678 | M36: 17.218008 | N36: 14.518538 | O36: - | P36: - | Q36: 2.022473 | R36: 0 | S36: Overweight (1.43)
A37: Axcelis Technologies | B37: ACLS-US | C37: 06/30/2024 | D37: 98.860001 | E37: 149 | F37: 2714.4344 | G37: 3259.5834 | H37: -474.887 | I37: 2.914752 | J37: 2.442141 | K37: 11.954388 | L37: 9.960121 | M37: 16.306805 | N37: 13.350439 | O37: - | P37: - | Q37: 3.166883 | R37: 0 | S37: Overweight (1.33)
A38: ACM Research A | B38: ACMR-US | C38: 06/30/2024 | D38: 16.370001 | E38: 34.75 | F38: 1001.2794 | G38: 1091.7073 | H38: -220.497 | I38: 1.582755 | J38: 1.443679 | K38: 6.808934 | L38: 5.627979 | M38: 10.35257 | N38: 8.927062 | O38: - | P38: - | Q38: -10.823777 | R38: 0 | S38: Buy (1.00)
A39: PDF Solutions | B39: PDFS-US | C39: 06/30/2024 | D39: 29.190001 | E39: 42.75 | F39: 1060.9434 | G39: 1178.8184 | H39: -112.263 | I39: 6.862665 | J39: 6.3741 | K39: - | L39: - | M39: 37.066666 | N39: 28 | O39: - | P39: - | Q39: 0.2617 | R39: 0 | S39: Buy (1.00)
A40: Nova | B40: NVMI-US | C40: 06/30/2024 | D40: 189.27 | E40: 242.8 | F40: 5601.9528 | G40: 6141.4688 | H40: -296.564 | I40: 10.863557 | J40: 9.973513 | K40: 25.749385 | L40: 22.096192 | M40: 29.727446 | N40: 25.977121 | O40: 32.689121 | P40: 27.390739 | Q40: 2.412113 | R40: 0 | S40: Overweight (1.33)
A41: Average | I41: 6.576154 | J41: 6.338156 | K41: 18.128595 | L41: 14.700119 | M41: 24.081237 | N41: 19.185646 | O41: 32.603687 | P41: 24.669204 | Q41: 1.203889 | R41: -
A42: Median | I42: 6.716649 | J42: 6.3741 | K42: 18.113471 | L42: 15.123898 | M42: 21.987379 | N42: 19.192108 | O42: 24.115273 | P42: 22.605446 | Q42: 2.412113 | R42: 0

Sheet 5 Forces
B1: Porters 5 forces | C1: Current | D1: 5-10 year
A2: 1 | B2: Compettive Rivalry | C2: 5 | D2: 5
A3: 2 | B3: Threat of subsitutes | C3: 1 | D3: 1
A4: 3 | B4: Threat of Entry | C4: 1 | D4: 1
A5: 4 | B5: Bargaining power of Buyers | C5: 4 | D5: 3
A6: 5 | B6: Bargaining power of Suppliers | C6: 3 | D6: 3
B33: DCF Porter Analysis for AMAT
B34: Hiver Porter Analysis for AMAT
B35: Porter Analysis of AMAT
